<mujoco model="RM75-6F.STEP.SLDASM">
  <option timestep="0.0003" integrator="implicitfast">
		<flag sensornoise="enable" energy="enable" contact="disable"/>
	</option>
  <compiler angle="radian" meshdir="../meshes/"/>
  <asset>
    <mesh name="base_link" file="base_link.STL"/>
    <mesh name="link1" file="link1.STL"/>
    <mesh name="link2" file="link2.STL"/>
    <mesh name="link3" file="link3.STL"/>
    <mesh name="link4" file="link4.STL"/>
    <mesh name="link5" file="link5.STL"/>
    <mesh name="link6" file="link6.STL"/>
    <mesh name="link7" file="link7.STL"/>
    <texture type="skybox" builtin="gradient" rgb1="0.3 0.5 0.7" rgb2="0 0 0" width="512" height="3072"/>
        <!-- <texture builtin="flat" height="1278" mark="cross" markrgb="1 1 1" name="texgeom" random="0.01" rgb1="0.8 0.6 0.4" rgb2="0.8 0.6 0.4" type="cube" width="127"/> -->
        <!-- <material name="geom" texture="texgeom" texuniform="true"/> -->
        <texture type="2d" name="groundplane" builtin="checker" mark="edge" rgb1="0.2 0.3 0.4" rgb2="0.1 0.2 0.3"
      markrgb="0.8 0.8 0.8" width="300" height="300"/>
        <material name="groundplane" texture="groundplane" texuniform="true" texrepeat="5 5" reflectance="0.2"/>
  </asset>
  <worldbody>
    <light diffuse="0.6 0.6 0.6" pos="0 0 3"/>
    <light diffuse="0.6 0.6 0.6" pos="0 -0.3 3" dir="0 0.2 -0.8" directional="true"/>
    <!-- <light cutoff="100" diffuse="0.5 0.5 0.5" dir="-0 0 -1.3" directional="true" exponent="1" pos="0 0 1.3" specular=".1 .1 .1"/> -->
    <geom name="floor" size="0 0 0.05" type="plane" material="groundplane"/>
    
    <geom type="mesh" contype="0" conaffinity="0" group="1" density="0" rgba="0.79216 0.81961 0.93333 1" mesh="base_link"/>
    <geom type="mesh" rgba="0.79216 0.81961 0.93333 1" mesh="base_link"/>
    <body name="link1" pos="0 0 0.1495">
      <inertial pos="0 0 0" quat="0.699375 0.105274 0.105308 0.699073" mass="0.59356" diaginertia="0.0012661 0.00124679 0.000496262"/>
      <joint name="joint1" pos="0 0 0" axis="0 0 -1" range="-3.14 3.14"/>
      <geom type="mesh" contype="0" conaffinity="0" group="1" density="0" rgba="0.79216 0.81961 0.93333 1" mesh="link1"/>
      <geom type="mesh" rgba="0.79216 0.81961 0.93333 1" mesh="link1"/>
      <body name="link2" pos="-0.006471 0 0.091" quat="0.5 0.5 0.5 0.5">
        <inertial pos="0 0 0" quat="0.426361 0.564049 -0.564124 0.426414" mass="0.43285" diaginertia="0.0013015 0.0012584 0.000238366"/>
        <joint name="joint2" pos="0 0 0" axis="0 0 -1" range="-3.14 3.14"/>
        <geom type="mesh" contype="0" conaffinity="0" group="1" density="0" rgba="0.79216 0.81961 0.93333 1" mesh="link2"/>
        <geom type="mesh" rgba="0.79216 0.81961 0.93333 1" mesh="link2"/>
        <body name="link3" pos="0 0.1495 0.006471" quat="0.612 -0.612 0.354 0.354">
          <inertial pos="0 0 0" quat="0.699221 0.105971 0.10601 0.699015" mass="0.431325" diaginertia="0.00079434 0.000774627 0.0002708"/>
          <joint name="joint3" pos="0 0 0" axis="0 0 1" range="-3.14 3.14"/>
          <geom type="mesh" contype="0" conaffinity="0" group="1" density="0" rgba="0.792157 0.819608 0.933333 1" mesh="link3"/>
          <geom type="mesh" rgba="0.792157 0.819608 0.933333 1" mesh="link3"/>
          <body name="link4" pos="-0.011436 0.000316 0.1065" quat="0.5 0.5 0.5 0.5">
          <!-- <body name="link4" pos="-0.011436 0.000316 0.1065" quat="0 0.707 0 0.707"> -->
            <inertial pos="0 0 0" quat="0.424973 0.565517 -0.564997 0.424695" mass="0.28965" diaginertia="0.000656042 0.00063737 0.000114628"/>
            <joint name="joint4" pos="0 0 0" axis="0 0 -1" range="-3.14 3.14"/>
            <geom type="mesh" contype="0" conaffinity="0" group="1" density="0" rgba="0.79216 0.81961 0.93333 1" mesh="link4"/>
            <geom type="mesh" rgba="0.79216 0.81961 0.93333 1" mesh="link4"/>
            <body name="link5" pos="-0.000316 0.1285 0.011436" quat="0.5 -0.5 0.5 0.5">
              <inertial pos="0 0 0" quat="0.700248 0.0977239 0.097714 0.700396" mass="0.23942" diaginertia="0.00028594 0.00027532 0.0001073"/>
              <joint name="joint5" pos="0 0 0" axis="0 0 -1" range="-3.14 3.14"/>
              <geom type="mesh" contype="0" conaffinity="0" group="1" density="0" rgba="0.79216 0.81961 0.93333 1" mesh="link5"/>
              <geom type="mesh" rgba="0.79216 0.81961 0.93333 1" mesh="link5"/>
              <body name="link6" pos="-0.009436 0 0.0815" quat="0 0.707 0 0.707">
                <inertial pos="0 0 0" quat="0.420058 0.569215 -0.568643 0.419751" mass="0.21879" diaginertia="0.000358601 0.00035053 8.07893e-05"/>
                <joint name="joint6" pos="0 0 0" axis="0 0 -1" range="-3.14 3.14"/>
                <geom type="mesh" contype="0" conaffinity="0" group="1" density="0" rgba="0.79216 0.81961 0.93333 1" mesh="link6"/>
                <geom type="mesh" rgba="0.79216 0.81961 0.93333 1" mesh="link6"/>
                <body name="link7" pos="0 0.115 0.009436" quat="0.5 -0.5 0.5 0.5">
                  <inertial pos="0 0 0" quat="0.184288 0.682541 -0.185247 0.682539" mass="0.14433" diaginertia="6.1463e-05 3.68926e-05 3.38524e-05"/>
                  <joint name="joint7" pos="0 0 0" axis="0 0 -1" range="-3.14 3.14"/>
                  <geom type="mesh" contype="0" conaffinity="0" group="1" density="0" rgba="1 1 1 1" mesh="link7"/>
                  <geom type="mesh" rgba="1 1 1 1" mesh="link7"/>
                </body>
              </body>
            </body>
          </body>
        </body>
      </body>
    </body>
  </worldbody>
  <actuator>


    <position name="joint1" ctrllimited="true" ctrlrange="-3.14 3.14" joint="joint1" kp="50"/>
    <position name="joint2" ctrllimited="true" ctrlrange="-3.14 3.14" joint="joint2" kp="50"/>
    <position name="joint3" ctrllimited="true" ctrlrange="-3.14 3.14" joint="joint3" kp="50"/>
    <position name="joint4" ctrllimited="true" ctrlrange="-3.14 3.14" joint="joint4" kp="50"/>
    <position name="joint5" ctrllimited="true" ctrlrange="-3.14 3.14" joint="joint5" kp="50"/>
    <position name="joint6" ctrllimited="true" ctrlrange="-3.14 3.14" joint="joint6" kp="50"/>     
    <position name="joint7" ctrllimited="true" ctrlrange="-3.14 3.14" joint="joint7" kp="50"/> 

    <!-- <motor name="mjoint1" gear="3" ctrllimited="true" ctrlrange="-100 100" joint="joint1" />
    <motor name="mjoint2" gear="3" ctrllimited="true" ctrlrange="-100 100" joint="joint2" />
    <motor name="mjoint3" gear="3" ctrllimited="true" ctrlrange="-100 100" joint="joint3" />
    <motor name="mjoint4" gear="3" ctrllimited="true" ctrlrange="-100 100" joint="joint4" />
    <motor name="mjoint5" gear="3" ctrllimited="true" ctrlrange="-100 100" joint="joint5" />
    <motor name="mjoint6" gear="3" ctrllimited="true" ctrlrange="-100 100" joint="joint6" />     
    <motor name="mjoint7" gear="3" ctrllimited="true" ctrlrange="-100 100" joint="joint7" /> -->
   
    <velocity name="vjoint1" ctrllimited="true" ctrlrange="-3.14159 3.14159" joint="joint1" kv="80"/>
    <velocity name="vjoint2" ctrllimited="true" ctrlrange="-3.14159 3.14159" joint="joint2" kv="80"/>
    <velocity name="vjoint3" ctrllimited="true" ctrlrange="-3.14159 3.14159" joint="joint3" kv="80"/>
    <velocity name="vjoint4" ctrllimited="true" ctrlrange="-3.14159 3.14159" joint="joint4" kv="80"/>
    <velocity name="vjoint5" ctrllimited="true" ctrlrange="-3.14159 3.14159" joint="joint5" kv="80"/>
    <velocity name="vjoint6" ctrllimited="true" ctrlrange="-3.14159 3.14159" joint="joint6" kv="80"/>     
    <velocity name="vjoint7" ctrllimited="true" ctrlrange="-3.14159 3.14159" joint="joint7" kv="80"/>  


  </actuator>
</mujoco>
